Workbook
Name checkInd: CheckSum!$A$103
Name CheckSumHigh: IFERROR(MMULT(TRANSPOSE(CS_Seq1),CS_TableHigh),0)
Name CheckSumLow: IFERROR(MMULT(TRANSPOSE(CS_Seq1),CS_TableLow),0)
Name CheckSumSortCity: IFERROR(SUMPRODUCT(CS_Seq1,CODE(CS_SortCity)),0)
Name CheckSumSortTemp: SUMPRODUCT(CS_SortTemp,CS_Seq1)
Name CS_Int: CheckSum!$A$2:$A$51
Name CS_Seq1: CheckSum!$B$2:$B$51
Name CS_SortCity: MonthSorted!$B$5:$B$54
Name CS_SortTemp: MonthSorted!$C$5:$C$54
Name CS_TableHigh: SummaryHigh!$D$5:$O$54
Name CS_TableLow: SummaryLow!$D$5:$O$54
Name ListCity: CheckSum!$D$2:$D$51
Name ListsMonthShort: CheckSum!$E$2:$P$2

Sheet CheckSum
A1: CS_Int | B1: CS_Seq1 | D1: ListCity | E1: ListMonthShort
A2: 1 | B2: 2 | D2: Atlanta | E2: Jan | F2: Feb | G2: Mar | H2: Apr | I2: May | J2: Jun | K2: Jul | L2: Aug | M2: Sep | N2: Oct | O2: Nov | P2: Dec
A3: 2 | B3: 3 | D3: Austin
A4: 3 | B4: 5 | D4: Baltimore
A5: 4 | B5: 7 | D5: Birmingham
A6: 5 | B6: 11 | D6: Boston
A7: 6 | B7: 13 | D7: Buffalo
A8: 7 | B8: 17 | D8: Charlotte
A9: 8 | B9: 19 | D9: Chicago
A10: 9 | B10: 23 | D10: Cincinnati
A11: 10 | B11: 29 | D11: Cleveland
A12: 11 | B12: 31 | D12: Columbus
A13: 12 | B13: 37 | D13: Dallas
A14: 13 | B14: 41 | D14: Denver
... A51: 50 | B51: 229 | D51: Virginia Beach

Sheet Introduction
H2: Excel Skills for Business: Advanced
H4: End of Course - Assignment
I6: Final Assignment

Sheet Part 1
A1: This sheet is intentionally blank

Sheet Data1
A1: Temperature Data
A2: Atlanta | B2: Georgia | C2: M1H52L34 | D2: M2H57L38 | E2: M3H65L44 | F2: M4H73L52 | G2: M5H8ØL6Ø | H2: M6H86L68 | I2: M7H89L71 | J2: M8H88L71 | K2: M9H82L65 | L2: M1ØH73L54 | M2: M11H64L45 | N2: M12H54L37
A3: Austin | B3: Texas | C3: M1H62L42 | D3: M2H65L45 | E3: M3H72L51 | F3: M4H8ØL59 | G3: M5H87L67 | H3: M6H92L72 | I3: M7H96L74 | J3: M8H97L75 | K3: M9H91L69 | L3: M1ØH82L61 | M3: M11H71L51 | N3: M12H63L42
A4: Baltimore | B4: Maryland | C4: M1H41L24 | D4: M2H45L27 | E4: M3H54L34 | F4: M4H65L43 | G4: M5H74L52 | H4: M6H83L62 | I4: M7H87L67 | J4: M8H85L65 | K4: M9H78L58 | L4: M1ØH67L45 | M4: M11H56L37 | N4: M12H45L28
A5: Birmingham | B5: Alabama | C5: M1H54L34 | D5: M2H58L37 | E5: M3H67L44 | F5: M4H74L51 | G5: M5H82L6Ø | H5: M6H88L68 | I5: M7H91L71 | J5: M8H91L71 | K5: M9H85L64 | L5: M1ØH75L53 | M5: M11H65L44 | N5: M12H56L36
A6: Boston | B6: Massachusetts | C6: M1H36L22 | D6: M2H39L25 | E6: M3H45L31 | F6: M4H56L41 | G6: M5H66L5Ø | H6: M6H76L6Ø | I6: M7H81L65 | J6: M8H8ØL65 | K6: M9H72L57 | L6: M1ØH61L47 | M6: M11H52L38 | N6: M12H41L28
A7: Buffalo | B7: New York | C7: M1H31L19 | D7: M2H33L19 | E7: M3H42L26 | F7: M4H55L37 | G7: M5H67L47 | H7: M6H75L57 | I7: M7H8ØL62 | J7: M8H78L61 | K7: M9H71L53 | L7: M1ØH59L43 | M7: M11H48L34 | N7: M12H36L24
A8: Charlotte | B8: North Carolina | C8: M1H51L3Ø | D8: M2H55L33 | E8: M3H63L39 | F8: M4H72L47 | G8: M5H79L56 | H8: M6H86L65 | I8: M7H89L68 | J8: M8H88L67 | K8: M9H81L6Ø | L8: M1ØH72L49 | M8: M11H62L39 | N8: M12H53L32
A9: Chicago | B9: Illinois | C9: M1H31L17 | D9: M2H35L2Ø | E9: M3H47L29 | F9: M4H59L39 | G9: M5H7ØL48 | H9: M6H8ØL58 | I9: M7H84L64 | J9: M8H82L63 | K9: M9H75L54 | L9: M1ØH62L43 | M9: M11H48L32 | N9: M12H35L21
A10: Cincinnati | B10: Ohio | C10: M1H4ØL22 | D10: M2H45L25 | E10: M3H55L33 | F10: M4H66L42 | G10: M5H75L52 | H10: M6H83L61 | I10: M7H87L65 | J10: M8H86L63 | K10: M9H79L55 | L10: M1ØH68L43 | M10: M11H56L34 | N10: M12H43L26
A11: Cleveland | B11: Ohio | C11: M1H34L22 | D11: M2H38L24 | E11: M3H47L3Ø | F11: M4H59L4Ø | G11: M5H7ØL5Ø | H11: M6H79L6Ø | I11: M7H83L64 | J11: M8H81L63 | K11: M9H74L56 | L11: M1ØH62L45 | M11: M11H51L37 | N11: M12H38L26
A12: Columbus | B12: Ohio | C12: M1H37L23 | D12: M2H41L25 | E12: M3H51L33 | F12: M4H64L43 | G12: M5H73L52 | H12: M6H82L62 | I12: M7H85L66 | J12: M8H84L64 | K12: M9H77L57 | L12: M1ØH65L45 | M12: M11H53L36 | N12: M12H4ØL27
A13: Dallas | B13: Texas | C13: M1H57L37 | D13: M2H61L41 | E13: M3H69L49 | F13: M4H77L56 | G13: M5H84L65 | H13: M6H92L73 | I13: M7H96L77 | J13: M8H96L77 | K13: M9H89L69 | L13: M1ØH79L58 | M13: M11H67L48 | N13: M12H58L39
... A51: Virginia Beach | B51: Virginia | C51: M1H48L33 | D51: M2H51L34 | E51: M3H58L41 | F51: M4H68L49 | G51: M5H75L58 | H51: M6H84L67 | I51: M7H87L72 | J51: M8H85L71 | K51: M9H79L65 | L51: M1ØH7ØL54 | M51: M11H61L45 | N51: M12H52L36

Sheet Workings_1

Sheet SummaryHigh
B3: Summary Table of High Temperatures - by Month
B4: City | C4: State | D4: {=ListsMonthShort} -> Jan | E4: Feb | F4: Mar | G4: Apr | H4: May | I4: Jun | J4: Jul | K4: Aug | L4: Sep | M4: Oct | N4: Nov | O4: Dec
B5: {=ListCity} -> Atlanta | D5: =VALUE(SUBSTITUTE(SUBSTITUTE( MID(Data1!C2, FIND("H", Data1!C2)+1, FIND("L", Data1!C2)-FIND("H", Data1!C2)-1), "Ø","0"), " ","")) -> 52 | E5: =VALUE(SUBSTITUTE(SUBSTITUTE( MID(Data1!D2, FIND("H", Data1!D2)+1, FIND("L", Data1!D2)-FIND("H", Data1!D2)-1), "Ø","0"), " ","")) -> 57 | F5: =VALUE(SUBSTITUTE(SUBSTITUTE( MID(Data1!E2, FIND("H", Data1!E2)+1, FIND("L", Data1!E2)-FIND("H", Data1!E2)-1), "Ø","0"), " ","")) -> 65 | G5: =VALUE(SUBSTITUTE(SUBSTITUTE( MID(Data1!F2, FIND("H", Data1!F2)+1, FIND("L", Data1!F2)-FIND("H", Data1!F2)-1), "Ø","0"), " ","")) -> 73 | H5: =VALUE(SUBSTITUTE(SUBSTITUTE( MID(Data1!G2, FIND("H", Data1!G2)+1, FIND("L", Data1!G2)-FIND("H", Data1!G2)-1), "Ø","0"), " ","")) -> 80 | I5: =VALUE(SUBSTITUTE(SUBSTITUTE( MID(Data1!H2, FIND("H", Data1!H2)+1, FIND("L", Data1!H2)-FIND("H", Data1!H2)-1), "Ø","0"), " ","")) -> 86 | J5: =VALUE(SUBSTITUTE(SUBSTITUTE( MID(Data1!I2, FIND("H", Data1!I2)+1, FIND("L", Data1!I2)-FIND("H", Data1!I2)-1), "Ø","0"), " ","")) -> 89 | K5: =VALUE(SUBSTITUTE(SUBSTITUTE( MID(Data1!J2, FIND("H", Data1!J2)+1, FIND("L", Data1!J2)-FIND("H", Data1!J2)-1), "Ø","0"), " ","")) -> 88 | ... O5: =VALUE(SUBSTITUTE(SUBSTITUTE( MID(Data1!N2, FIND("H", Data1!N2)+1, FIND("L", Data1!N2)-FIND("H", Data1!N2)-1), "Ø","0"), " ","")) -> 54
B6: Austin | D6: =VALUE(SUBSTITUTE(SUBSTITUTE( MID(Data1!C3, FIND("H", Data1!C3)+1, FIND("L", Data1!C3)-FIND("H", Data1!C3)-1), "Ø","0"), " ","")) -> 62 | E6: =VALUE(SUBSTITUTE(SUBSTITUTE( MID(Data1!D3, FIND("H", Data1!D3)+1, FIND("L", Data1!D3)-FIND("H", Data1!D3)-1), "Ø","0"), " ","")) -> 65 | F6: =VALUE(SUBSTITUTE(SUBSTITUTE( MID(Data1!E3, FIND("H", Data1!E3)+1, FIND("L", Data1!E3)-FIND("H", Data1!E3)-1), "Ø","0"), " ","")) -> 72 | G6: =VALUE(SUBSTITUTE(SUBSTITUTE( MID(Data1!F3, FIND("H", Data1!F3)+1, FIND("L", Data1!F3)-FIND("H", Data1!F3)-1), "Ø","0"), " ","")) -> 80 | H6: =VALUE(SUBSTITUTE(SUBSTITUTE( MID(Data1!G3, FIND("H", Data1!G3)+1, FIND("L", Data1!G3)-FIND("H", Data1!G3)-1), "Ø","0"), " ","")) -> 87 | I6: =VALUE(SUBSTITUTE(SUBSTITUTE( MID(Data1!H3, FIND("H", Data1!H3)+1, FIND("L", Data1!H3)-FIND("H", Data1!H3)-1), "Ø","0"), " ","")) -> 92 | J6: =VALUE(SUBSTITUTE(SUBSTITUTE( MID(Data1!I3, FIND("H", Data1!I3)+1, FIND("L", Data1!I3)-FIND("H", Data1!I3)-1), "Ø","0"), " ","")) -> 96 | K6: =VALUE(SUBSTITUTE(SUBSTITUTE( MID(Data1!J3, FIND("H", Data1!J3)+1, FIND("L", Data1!J3)-FIND("H", Data1!J3)-1), "Ø","0"), " ","")) -> 97 | ... O6: =VALUE(SUBSTITUTE(SUBSTITUTE( MID(Data1!N3, FIND("H", Data1!N3)+1, FIND("L", Data1!N3)-FIND("H", Data1!N3)-1), "Ø","0"), " ","")) -> 63 | Q6: =SUM(L5:O14) -> 2506
B7: Baltimore | D7: =VALUE(SUBSTITUTE(SUBSTITUTE( MID(Data1!C4, FIND("H", Data1!C4)+1, FIND("L", Data1!C4)-FIND("H", Data1!C4)-1), "Ø","0"), " ","")) -> 41 | E7: =VALUE(SUBSTITUTE(SUBSTITUTE( MID(Data1!D4, FIND("H", Data1!D4)+1, FIND("L", Data1!D4)-FIND("H", Data1!D4)-1), "Ø","0"), " ","")) -> 45 | F7: =VALUE(SUBSTITUTE(SUBSTITUTE( MID(Data1!E4, FIND("H", Data1!E4)+1, FIND("L", Data1!E4)-FIND("H", Data1!E4)-1), "Ø","0"), " ","")) -> 54 | G7: =VALUE(SUBSTITUTE(SUBSTITUTE( MID(Data1!F4, FIND("H", Data1!F4)+1, FIND("L", Data1!F4)-FIND("H", Data1!F4)-1), "Ø","0"), " ","")) -> 65 | H7: =VALUE(SUBSTITUTE(SUBSTITUTE( MID(Data1!G4, FIND("H", Data1!G4)+1, FIND("L", Data1!G4)-FIND("H", Data1!G4)-1), "Ø","0"), " ","")) -> 74 | I7: =VALUE(SUBSTITUTE(SUBSTITUTE( MID(Data1!H4, FIND("H", Data1!H4)+1, FIND("L", Data1!H4)-FIND("H", Data1!H4)-1), "Ø","0"), " ","")) -> 83 | J7: =VALUE(SUBSTITUTE(SUBSTITUTE( MID(Data1!I4, FIND("H", Data1!I4)+1, FIND("L", Data1!I4)-FIND("H", Data1!I4)-1), "Ø","0"), " ","")) -> 87 | K7: =VALUE(SUBSTITUTE(SUBSTITUTE( MID(Data1!J4, FIND("H", Data1!J4)+1, FIND("L", Data1!J4)-FIND("H", Data1!J4)-1), "Ø","0"), " ","")) -> 85 | ... O7: =VALUE(SUBSTITUTE(SUBSTITUTE( MID(Data1!N4, FIND("H", Data1!N4)+1, FIND("L", Data1!N4)-FIND("H", Data1!N4)-1), "Ø","0"), " ","")) -> 45
B8: Birmingham | D8: =VALUE(SUBSTITUTE(SUBSTITUTE( MID(Data1!C5, FIND("H", Data1!C5)+1, FIND("L", Data1!C5)-FIND("H", Data1!C5)-1), "Ø","0"), " ","")) -> 54 | E8: =VALUE(SUBSTITUTE(SUBSTITUTE( MID(Data1!D5, FIND("H", Data1!D5)+1, FIND("L", Data1!D5)-FIND("H", Data1!D5)-1), "Ø","0"), " ","")) -> 58 | F8: =VALUE(SUBSTITUTE(SUBSTITUTE( MID(Data1!E5, FIND("H", Data1!E5)+1, FIND("L", Data1!E5)-FIND("H", Data1!E5)-1), "Ø","0"), " ","")) -> 67 | G8: =VALUE(SUBSTITUTE(SUBSTITUTE( MID(Data1!F5, FIND("H", Data1!F5)+1, FIND("L", Data1!F5)-FIND("H", Data1!F5)-1), "Ø","0"), " ","")) -> 74 | H8: =VALUE(SUBSTITUTE(SUBSTITUTE( MID(Data1!G5, FIND("H", Data1!G5)+1, FIND("L", Data1!G5)-FIND("H", Data1!G5)-1), "Ø","0"), " ","")) -> 82 | I8: =VALUE(SUBSTITUTE(SUBSTITUTE( MID(Data1!H5, FIND("H", Data1!H5)+1, FIND("L", Data1!H5)-FIND("H", Data1!H5)-1), "Ø","0"), " ","")) -> 88 | J8: =VALUE(SUBSTITUTE(SUBSTITUTE( MID(Data1!I5, FIND("H", Data1!I5)+1, FIND("L", Data1!I5)-FIND("H", Data1!I5)-1), "Ø","0"), " ","")) -> 91 | K8: =VALUE(SUBSTITUTE(SUBSTITUTE( MID(Data1!J5, FIND("H", Data1!J5)+1, FIND("L", Data1!J5)-FIND("H", Data1!J5)-1), "Ø","0"), " ","")) -> 91 | ... O8: =VALUE(SUBSTITUTE(SUBSTITUTE( MID(Data1!N5, FIND("H", Data1!N5)+1, FIND("L", Data1!N5)-FIND("H", Data1!N5)-1), "Ø","0"), " ","")) -> 56
B9: Boston | D9: =VALUE(SUBSTITUTE(SUBSTITUTE( MID(Data1!C6, FIND("H", Data1!C6)+1, FIND("L", Data1!C6)-FIND("H", Data1!C6)-1), "Ø","0"), " ","")) -> 36 | E9: =VALUE(SUBSTITUTE(SUBSTITUTE( MID(Data1!D6, FIND("H", Data1!D6)+1, FIND("L", Data1!D6)-FIND("H", Data1!D6)-1), "Ø","0"), " ","")) -> 39 | F9: =VALUE(SUBSTITUTE(SUBSTITUTE( MID(Data1!E6, FIND("H", Data1!E6)+1, FIND("L", Data1!E6)-FIND("H", Data1!E6)-1), "Ø","0"), " ","")) -> 45 | G9: =VALUE(SUBSTITUTE(SUBSTITUTE( MID(Data1!F6, FIND("H", Data1!F6)+1, FIND("L", Data1!F6)-FIND("H", Data1!F6)-1), "Ø","0"), " ","")) -> 56 | H9: =VALUE(SUBSTITUTE(SUBSTITUTE( MID(Data1!G6, FIND("H", Data1!G6)+1, FIND("L", Data1!G6)-FIND("H", Data1!G6)-1), "Ø","0"), " ","")) -> 66 | I9: =VALUE(SUBSTITUTE(SUBSTITUTE( MID(Data1!H6, FIND("H", Data1!H6)+1, FIND("L", Data1!H6)-FIND("H", Data1!H6)-1), "Ø","0"), " ","")) -> 76 | J9: =VALUE(SUBSTITUTE(SUBSTITUTE( MID(Data1!I6, FIND("H", Data1!I6)+1, FIND("L", Data1!I6)-FIND("H", Data1!I6)-1), "Ø","0"), " ","")) -> 81 | K9: =VALUE(SUBSTITUTE(SUBSTITUTE( MID(Data1!J6, FIND("H", Data1!J6)+1, FIND("L", Data1!J6)-FIND("H", Data1!J6)-1), "Ø","0"), " ","")) -> 80 | ... O9: =VALUE(SUBSTITUTE(SUBSTITUTE( MID(Data1!N6, FIND("H", Data1!N6)+1, FIND("L", Data1!N6)-FIND("H", Data1!N6)-1), "Ø","0"), " ","")) -> 41
B10: Buffalo | D10: =VALUE(SUBSTITUTE(SUBSTITUTE( MID(Data1!C7, FIND("H", Data1!C7)+1, FIND("L", Data1!C7)-FIND("H", Data1!C7)-1), "Ø","0"), " ","")) -> 31 | E10: =VALUE(SUBSTITUTE(SUBSTITUTE( MID(Data1!D7, FIND("H", Data1!D7)+1, FIND("L", Data1!D7)-FIND("H", Data1!D7)-1), "Ø","0"), " ","")) -> 33 | F10: =VALUE(SUBSTITUTE(SUBSTITUTE( MID(Data1!E7, FIND("H", Data1!E7)+1, FIND("L", Data1!E7)-FIND("H", Data1!E7)-1), "Ø","0"), " ","")) -> 42 | G10: =VALUE(SUBSTITUTE(SUBSTITUTE( MID(Data1!F7, FIND("H", Data1!F7)+1, FIND("L", Data1!F7)-FIND("H", Data1!F7)-1), "Ø","0"), " ","")) -> 55 | H10: =VALUE(SUBSTITUTE(SUBSTITUTE( MID(Data1!G7, FIND("H", Data1!G7)+1, FIND("L", Data1!G7)-FIND("H", Data1!G7)-1), "Ø","0"), " ","")) -> 67 | I10: =VALUE(SUBSTITUTE(SUBSTITUTE( MID(Data1!H7, FIND("H", Data1!H7)+1, FIND("L", Data1!H7)-FIND("H", Data1!H7)-1), "Ø","0"), " ","")) -> 75 | J10: =VALUE(SUBSTITUTE(SUBSTITUTE( MID(Data1!I7, FIND("H", Data1!I7)+1, FIND("L", Data1!I7)-FIND("H", Data1!I7)-1), "Ø","0"), " ","")) -> 80 | K10: =VALUE(SUBSTITUTE(SUBSTITUTE( MID(Data1!J7, FIND("H", Data1!J7)+1, FIND("L", Data1!J7)-FIND("H", Data1!J7)-1), "Ø","0"), " ","")) -> 78 | ... O10: =VALUE(SUBSTITUTE(SUBSTITUTE( MID(Data1!N7, FIND("H", Data1!N7)+1, FIND("L", Data1!N7)-FIND("H", Data1!N7)-1), "Ø","0"), " ","")) -> 36
B11: Charlotte | D11: =VALUE(SUBSTITUTE(SUBSTITUTE( MID(Data1!C8, FIND("H", Data1!C8)+1, FIND("L", Data1!C8)-FIND("H", Data1!C8)-1), "Ø","0"), " ","")) -> 51 | E11: =VALUE(SUBSTITUTE(SUBSTITUTE( MID(Data1!D8, FIND("H", Data1!D8)+1, FIND("L", Data1!D8)-FIND("H", Data1!D8)-1), "Ø","0"), " ","")) -> 55 | F11: =VALUE(SUBSTITUTE(SUBSTITUTE( MID(Data1!E8, FIND("H", Data1!E8)+1, FIND("L", Data1!E8)-FIND("H", Data1!E8)-1), "Ø","0"), " ","")) -> 63 | G11: =VALUE(SUBSTITUTE(SUBSTITUTE( MID(Data1!F8, FIND("H", Data1!F8)+1, FIND("L", Data1!F8)-FIND("H", Data1!F8)-1), "Ø","0"), " ","")) -> 72 | H11: =VALUE(SUBSTITUTE(SUBSTITUTE( MID(Data1!G8, FIND("H", Data1!G8)+1, FIND("L", Data1!G8)-FIND("H", Data1!G8)-1), "Ø","0"), " ","")) -> 79 | I11: =VALUE(SUBSTITUTE(SUBSTITUTE( MID(Data1!H8, FIND("H", Data1!H8)+1, FIND("L", Data1!H8)-FIND("H", Data1!H8)-1), "Ø","0"), " ","")) -> 86 | J11: =VALUE(SUBSTITUTE(SUBSTITUTE( MID(Data1!I8, FIND("H", Data1!I8)+1, FIND("L", Data1!I8)-FIND("H", Data1!I8)-1), "Ø","0"), " ","")) -> 89 | K11: =VALUE(SUBSTITUTE(SUBSTITUTE( MID(Data1!J8, FIND("H", Data1!J8)+1, FIND("L", Data1!J8)-FIND("H", Data1!J8)-1), "Ø","0"), " ","")) -> 88 | ... O11: =VALUE(SUBSTITUTE(SUBSTITUTE( MID(Data1!N8, FIND("H", Data1!N8)+1, FIND("L", Data1!N8)-FIND("H", Data1!N8)-1), "Ø","0"), " ","")) -> 53
B12: Chicago | D12: =VALUE(SUBSTITUTE(SUBSTITUTE( MID(Data1!C9, FIND("H", Data1!C9)+1, FIND("L", Data1!C9)-FIND("H", Data1!C9)-1), "Ø","0"), " ","")) -> 31 | E12: =VALUE(SUBSTITUTE(SUBSTITUTE( MID(Data1!D9, FIND("H", Data1!D9)+1, FIND("L", Data1!D9)-FIND("H", Data1!D9)-1), "Ø","0"), " ","")) -> 35 | F12: =VALUE(SUBSTITUTE(SUBSTITUTE( MID(Data1!E9, FIND("H", Data1!E9)+1, FIND("L", Data1!E9)-FIND("H", Data1!E9)-1), "Ø","0"), " ","")) -> 47 | G12: =VALUE(SUBSTITUTE(SUBSTITUTE( MID(Data1!F9, FIND("H", Data1!F9)+1, FIND("L", Data1!F9)-FIND("H", Data1!F9)-1), "Ø","0"), " ","")) -> 59 | H12: =VALUE(SUBSTITUTE(SUBSTITUTE( MID(Data1!G9, FIND("H", Data1!G9)+1, FIND("L", Data1!G9)-FIND("H", Data1!G9)-1), "Ø","0"), " ","")) -> 70 | I12: =VALUE(SUBSTITUTE(SUBSTITUTE( MID(Data1!H9, FIND("H", Data1!H9)+1, FIND("L", Data1!H9)-FIND("H", Data1!H9)-1), "Ø","0"), " ","")) -> 80 | J12: =VALUE(SUBSTITUTE(SUBSTITUTE( MID(Data1!I9, FIND("H", Data1!I9)+1, FIND("L", Data1!I9)-FIND("H", Data1!I9)-1), "Ø","0"), " ","")) -> 84 | K12: =VALUE(SUBSTITUTE(SUBSTITUTE( MID(Data1!J9, FIND("H", Data1!J9)+1, FIND("L", Data1!J9)-FIND("H", Data1!J9)-1), "Ø","0"), " ","")) -> 82 | ... O12: =VALUE(SUBSTITUTE(SUBSTITUTE( MID(Data1!N9, FIND("H", Data1!N9)+1, FIND("L", Data1!N9)-FIND("H", Data1!N9)-1), "Ø","0"), " ","")) -> 35
B13: Cincinnati | D13: =VALUE(SUBSTITUTE(SUBSTITUTE( MID(Data1!C10, FIND("H", Data1!C10)+1, FIND("L", Data1!C10)-FIND("H", Data1!C10)-1), "Ø","0"), " ","")) -> 40 | E13: =VALUE(SUBSTITUTE(SUBSTITUTE( MID(Data1!D10, FIND("H", Data1!D10)+1, FIND("L", Data1!D10)-FIND("H", Data1!D10)-1), "Ø","0"), " ","")) -> 45 | F13: =VALUE(SUBSTITUTE(SUBSTITUTE( MID(Data1!E10, FIND("H", Data1!E10)+1, FIND("L", Data1!E10)-FIND("H", Data1!E10)-1), "Ø","0"), " ","")) -> 55 | G13: =VALUE(SUBSTITUTE(SUBSTITUTE( MID(Data1!F10, FIND("H", Data1!F10)+1, FIND("L", Data1!F10)-FIND("H", Data1!F10)-1), "Ø","0"), " ","")) -> 66 | H13: =VALUE(SUBSTITUTE(SUBSTITUTE( MID(Data1!G10, FIND("H", Data1!G10)+1, FIND("L", Data1!G10)-FIND("H", Data1!G10)-1), "Ø","0"), " ","")) -> 75 | I13: =VALUE(SUBSTITUTE(SUBSTITUTE( MID(Data1!H10, FIND("H", Data1!H10)+1, FIND("L", Data1!H10)-FIND("H", Data1!H10)-1), "Ø","0"), " ","")) -> 83 | J13: =VALUE(SUBSTITUTE(SUBSTITUTE( MID(Data1!I10, FIND("H", Data1!I10)+1, FIND("L", Data1!I10)-FIND("H", Data1!I10)-1), "Ø","0"), " ","")) -> 87 | K13: =VALUE(SUBSTITUTE(SUBSTITUTE( MID(Data1!J10, FIND("H", Data1!J10)+1, FIND("L", Data1!J10)-FIND("H", Data1!J10)-1), "Ø","0"), " ","")) -> 86 | ... O13: =VALUE(SUBSTITUTE(SUBSTITUTE( MID(Data1!N10, FIND("H", Data1!N10)+1, FIND("L", Data1!N10)-FIND("H", Data1!N10)-1), "Ø","0"), " ","")) -> 43
B14: Cleveland | D14: =VALUE(SUBSTITUTE(SUBSTITUTE( MID(Data1!C11, FIND("H", Data1!C11)+1, FIND("L", Data1!C11)-FIND("H", Data1!C11)-1), "Ø","0"), " ","")) -> 34 | E14: =VALUE(SUBSTITUTE(SUBSTITUTE( MID(Data1!D11, FIND("H", Data1!D11)+1, FIND("L", Data1!D11)-FIND("H", Data1!D11)-1), "Ø","0"), " ","")) -> 38 | F14: =VALUE(SUBSTITUTE(SUBSTITUTE( MID(Data1!E11, FIND("H", Data1!E11)+1, FIND("L", Data1!E11)-FIND("H", Data1!E11)-1), "Ø","0"), " ","")) -> 47 | G14: =VALUE(SUBSTITUTE(SUBSTITUTE( MID(Data1!F11, FIND("H", Data1!F11)+1, FIND("L", Data1!F11)-FIND("H", Data1!F11)-1), "Ø","0"), " ","")) -> 59 | H14: =VALUE(SUBSTITUTE(SUBSTITUTE( MID(Data1!G11, FIND("H", Data1!G11)+1, FIND("L", Data1!G11)-FIND("H", Data1!G11)-1), "Ø","0"), " ","")) -> 70 | I14: =VALUE(SUBSTITUTE(SUBSTITUTE( MID(Data1!H11, FIND("H", Data1!H11)+1, FIND("L", Data1!H11)-FIND("H", Data1!H11)-1), "Ø","0"), " ","")) -> 79 | J14: =VALUE(SUBSTITUTE(SUBSTITUTE( MID(Data1!I11, FIND("H", Data1!I11)+1, FIND("L", Data1!I11)-FIND("H", Data1!I11)-1), "Ø","0"), " ","")) -> 83 | K14: =VALUE(SUBSTITUTE(SUBSTITUTE( MID(Data1!J11, FIND("H", Data1!J11)+1, FIND("L", Data1!J11)-FIND("H", Data1!J11)-1), "Ø","0"), " ","")) -> 81 | ... O14: =VALUE(SUBSTITUTE(SUBSTITUTE( MID(Data1!N11, FIND("H", Data1!N11)+1, FIND("L", Data1!N11)-FIND("H", Data1!N11)-1), "Ø","0"), " ","")) -> 38
B15: Columbus | D15: =VALUE(SUBSTITUTE(SUBSTITUTE( MID(Data1!C12, FIND("H", Data1!C12)+1, FIND("L", Data1!C12)-FIND("H", Data1!C12)-1), "Ø","0"), " ","")) -> 37 | E15: =VALUE(SUBSTITUTE(SUBSTITUTE( MID(Data1!D12, FIND("H", Data1!D12)+1, FIND("L", Data1!D12)-FIND("H", Data1!D12)-1), "Ø","0"), " ","")) -> 41 | F15: =VALUE(SUBSTITUTE(SUBSTITUTE( MID(Data1!E12, FIND("H", Data1!E12)+1, FIND("L", Data1!E12)-FIND("H", Data1!E12)-1), "Ø","0"), " ","")) -> 51 | G15: =VALUE(SUBSTITUTE(SUBSTITUTE( MID(Data1!F12, FIND("H", Data1!F12)+1, FIND("L", Data1!F12)-FIND("H", Data1!F12)-1), "Ø","0"), " ","")) -> 64 | H15: =VALUE(SUBSTITUTE(SUBSTITUTE( MID(Data1!G12, FIND("H", Data1!G12)+1, FIND("L", Data1!G12)-FIND("H", Data1!G12)-1), "Ø","0"), " ","")) -> 73 | I15: =VALUE(SUBSTITUTE(SUBSTITUTE( MID(Data1!H12, FIND("H", Data1!H12)+1, FIND("L", Data1!H12)-FIND("H", Data1!H12)-1), "Ø","0"), " ","")) -> 82 | J15: =VALUE(SUBSTITUTE(SUBSTITUTE( MID(Data1!I12, FIND("H", Data1!I12)+1, FIND("L", Data1!I12)-FIND("H", Data1!I12)-1), "Ø","0"), " ","")) -> 85 | K15: =VALUE(SUBSTITUTE(SUBSTITUTE( MID(Data1!J12, FIND("H", Data1!J12)+1, FIND("L", Data1!J12)-FIND("H", Data1!J12)-1), "Ø","0"), " ","")) -> 84 | ... O15: =VALUE(SUBSTITUTE(SUBSTITUTE( MID(Data1!N12, FIND("H", Data1!N12)+1, FIND("L", Data1!N12)-FIND("H", Data1!N12)-1), "Ø","0"), " ","")) -> 40
B16: Dallas | D16: =VALUE(SUBSTITUTE(SUBSTITUTE( MID(Data1!C13, FIND("H", Data1!C13)+1, FIND("L", Data1!C13)-FIND("H", Data1!C13)-1), "Ø","0"), " ","")) -> 57 | E16: =VALUE(SUBSTITUTE(SUBSTITUTE( MID(Data1!D13, FIND("H", Data1!D13)+1, FIND("L", Data1!D13)-FIND("H", Data1!D13)-1), "Ø","0"), " ","")) -> 61 | F16: =VALUE(SUBSTITUTE(SUBSTITUTE( MID(Data1!E13, FIND("H", Data1!E13)+1, FIND("L", Data1!E13)-FIND("H", Data1!E13)-1), "Ø","0"), " ","")) -> 69 | G16: =VALUE(SUBSTITUTE(SUBSTITUTE( MID(Data1!F13, FIND("H", Data1!F13)+1, FIND("L", Data1!F13)-FIND("H", Data1!F13)-1), "Ø","0"), " ","")) -> 77 | H16: =VALUE(SUBSTITUTE(SUBSTITUTE( MID(Data1!G13, FIND("H", Data1!G13)+1, FIND("L", Data1!G13)-FIND("H", Data1!G13)-1), "Ø","0"), " ","")) -> 84 | I16: =VALUE(SUBSTITUTE(SUBSTITUTE( MID(Data1!H13, FIND("H", Data1!H13)+1, FIND("L", Data1!H13)-FIND("H", Data1!H13)-1), "Ø","0"), " ","")) -> 92 | J16: =VALUE(SUBSTITUTE(SUBSTITUTE( MID(Data1!I13, FIND("H", Data1!I13)+1, FIND("L", Data1!I13)-FIND("H", Data1!I13)-1), "Ø","0"), " ","")) -> 96 | K16: =VALUE(SUBSTITUTE(SUBSTITUTE( MID(Data1!J13, FIND("H", Data1!J13)+1, FIND("L", Data1!J13)-FIND("H", Data1!J13)-1), "Ø","0"), " ","")) -> 96 | ... O16: =VALUE(SUBSTITUTE(SUBSTITUTE( MID(Data1!N13, FIND("H", Data1!N13)+1, FIND("L", Data1!N13)-FIND("H", Data1!N13)-1), "Ø","0"), " ","")) -> 58
B17: Denver | D17: =VALUE(SUBSTITUTE(SUBSTITUTE( MID(Data1!C14, FIND("H", Data1!C14)+1, FIND("L", Data1!C14)-FIND("H", Data1!C14)-1), "Ø","0"), " ","")) -> 45 | E17: =VALUE(SUBSTITUTE(SUBSTITUTE( MID(Data1!D14, FIND("H", Data1!D14)+1, FIND("L", Data1!D14)-FIND("H", Data1!D14)-1), "Ø","0"), " ","")) -> 46 | F17: =VALUE(SUBSTITUTE(SUBSTITUTE( MID(Data1!E14, FIND("H", Data1!E14)+1, FIND("L", Data1!E14)-FIND("H", Data1!E14)-1), "Ø","0"), " ","")) -> 54 | G17: =VALUE(SUBSTITUTE(SUBSTITUTE( MID(Data1!F14, FIND("H", Data1!F14)+1, FIND("L", Data1!F14)-FIND("H", Data1!F14)-1), "Ø","0"), " ","")) -> 61 | H17: =VALUE(SUBSTITUTE(SUBSTITUTE( MID(Data1!G14, FIND("H", Data1!G14)+1, FIND("L", Data1!G14)-FIND("H", Data1!G14)-1), "Ø","0"), " ","")) -> 71 | I17: =VALUE(SUBSTITUTE(SUBSTITUTE( MID(Data1!H14, FIND("H", Data1!H14)+1, FIND("L", Data1!H14)-FIND("H", Data1!H14)-1), "Ø","0"), " ","")) -> 81 | J17: =VALUE(SUBSTITUTE(SUBSTITUTE( MID(Data1!I14, FIND("H", Data1!I14)+1, FIND("L", Data1!I14)-FIND("H", Data1!I14)-1), "Ø","0"), " ","")) -> 88 | K17: =VALUE(SUBSTITUTE(SUBSTITUTE( MID(Data1!J14, FIND("H", Data1!J14)+1, FIND("L", Data1!J14)-FIND("H", Data1!J14)-1), "Ø","0"), " ","")) -> 86 | ... O17: =VALUE(SUBSTITUTE(SUBSTITUTE( MID(Data1!N14, FIND("H", Data1!N14)+1, FIND("L", Data1!N14)-FIND("H", Data1!N14)-1), "Ø","0"), " ","")) -> 43
B18: Detroit | D18: =VALUE(SUBSTITUTE(SUBSTITUTE( MID(Data1!C15, FIND("H", Data1!C15)+1, FIND("L", Data1!C15)-FIND("H", Data1!C15)-1), "Ø","0"), " ","")) -> 32 | E18: =VALUE(SUBSTITUTE(SUBSTITUTE( MID(Data1!D15, FIND("H", Data1!D15)+1, FIND("L", Data1!D15)-FIND("H", Data1!D15)-1), "Ø","0"), " ","")) -> 35 | F18: =VALUE(SUBSTITUTE(SUBSTITUTE( MID(Data1!E15, FIND("H", Data1!E15)+1, FIND("L", Data1!E15)-FIND("H", Data1!E15)-1), "Ø","0"), " ","")) -> 46 | G18: =VALUE(SUBSTITUTE(SUBSTITUTE( MID(Data1!F15, FIND("H", Data1!F15)+1, FIND("L", Data1!F15)-FIND("H", Data1!F15)-1), "Ø","0"), " ","")) -> 59 | H18: =VALUE(SUBSTITUTE(SUBSTITUTE( MID(Data1!G15, FIND("H", Data1!G15)+1, FIND("L", Data1!G15)-FIND("H", Data1!G15)-1), "Ø","0"), " ","")) -> 70 | I18: =VALUE(SUBSTITUTE(SUBSTITUTE( MID(Data1!H15, FIND("H", Data1!H15)+1, FIND("L", Data1!H15)-FIND("H", Data1!H15)-1), "Ø","0"), " ","")) -> 79 | J18: =VALUE(SUBSTITUTE(SUBSTITUTE( MID(Data1!I15, FIND("H", Data1!I15)+1, FIND("L", Data1!I15)-FIND("H", Data1!I15)-1), "Ø","0"), " ","")) -> 83 | K18: =VALUE(SUBSTITUTE(SUBSTITUTE( MID(Data1!J15, FIND("H", Data1!J15)+1, FIND("L", Data1!J15)-FIND("H", Data1!J15)-1), "Ø","0"), " ","")) -> 81 | ... O18: =VALUE(SUBSTITUTE(SUBSTITUTE( MID(Data1!N15, FIND("H", Data1!N15)+1, FIND("L", Data1!N15)-FIND("H", Data1!N15)-1), "Ø","0"), " ","")) -> 36
... B54: Virginia Beach | D54: =VALUE(SUBSTITUTE(SUBSTITUTE( MID(Data1!C51, FIND("H", Data1!C51)+1, FIND("L", Data1!C51)-FIND("H", Data1!C51)-1), "Ø","0"), " ","")) -> 48 | E54: =VALUE(SUBSTITUTE(SUBSTITUTE( MID(Data1!D51, FIND("H", Data1!D51)+1, FIND("L", Data1!D51)-FIND("H", Data1!D51)-1), "Ø","0"), " ","")) -> 51 | F54: =VALUE(SUBSTITUTE(SUBSTITUTE( MID(Data1!E51, FIND("H", Data1!E51)+1, FIND("L", Data1!E51)-FIND("H", Data1!E51)-1), "Ø","0"), " ","")) -> 58 | G54: =VALUE(SUBSTITUTE(SUBSTITUTE( MID(Data1!F51, FIND("H", Data1!F51)+1, FIND("L", Data1!F51)-FIND("H", Data1!F51)-1), "Ø","0"), " ","")) -> 68 | H54: =VALUE(SUBSTITUTE(SUBSTITUTE( MID(Data1!G51, FIND("H", Data1!G51)+1, FIND("L", Data1!G51)-FIND("H", Data1!G51)-1), "Ø","0"), " ","")) -> 75 | I54: =VALUE(SUBSTITUTE(SUBSTITUTE( MID(Data1!H51, FIND("H", Data1!H51)+1, FIND("L", Data1!H51)-FIND("H", Data1!H51)-1), "Ø","0"), " ","")) -> 84 | J54: =VALUE(SUBSTITUTE(SUBSTITUTE( MID(Data1!I51, FIND("H", Data1!I51)+1, FIND("L", Data1!I51)-FIND("H", Data1!I51)-1), "Ø","0"), " ","")) -> 87 | K54: =VALUE(SUBSTITUTE(SUBSTITUTE( MID(Data1!J51, FIND("H", Data1!J51)+1, FIND("L", Data1!J51)-FIND("H", Data1!J51)-1), "Ø","0"), " ","")) -> 85 | ... O54: =VALUE(SUBSTITUTE(SUBSTITUTE( MID(Data1!N51, FIND("H", Data1!N51)+1, FIND("L", Data1!N51)-FIND("H", Data1!N51)-1), "Ø","0"), " ","")) -> 52
B55: Highest Temperatures | D55: =MAX(D5:D54) -> 76 | E55: =MAX(E5:E54) -> 78 | F55: =MAX(F5:F54) -> 80 | G55: =MAX(G5:G54) -> 86 | H55: =MAX(H5:H54) -> 95 | I55: =MAX(I5:I54) -> 104 | J55: =MAX(J5:J54) -> 106 | K55: =MAX(K5:K54) -> 104 | ... O55: =MAX(O5:O54) -> 78
B57: Check Sum | D57: {=CheckSumHigh} -> 259045 | E57: 277026 | F57: 312012 | G57: 352569 | H57: 390367 | I57: 425245 | J57: 445112 | K57: 441332 | L57: 413908 | M57: 366926 | N57: 314215 | O57: 268310

Sheet SummaryLow
B3: Summary Table of Low Temperatures - by Month
B4: City | C4: State | D4: {=ListsMonthShort} -> Jan | E4: Feb | F4: Mar | G4: Apr | H4: May | I4: Jun | J4: Jul | K4: Aug | L4: Sep | M4: Oct | N4: Nov | O4: Dec
B5: {=ListCity} -> Atlanta | D5: =VALUE(SUBSTITUTE(SUBSTITUTE(RIGHT(Data1!C2,LEN(Data1!C2)-FIND("L",Data1!C2)),"Ø","0")," ","")) -> 34 | E5: =VALUE(SUBSTITUTE(SUBSTITUTE(RIGHT(Data1!D2,LEN(Data1!D2)-FIND("L",Data1!D2)),"Ø","0")," ","")) -> 38 | F5: =VALUE(SUBSTITUTE(SUBSTITUTE(RIGHT(Data1!E2,LEN(Data1!E2)-FIND("L",Data1!E2)),"Ø","0")," ","")) -> 44 | G5: =VALUE(SUBSTITUTE(SUBSTITUTE(RIGHT(Data1!F2,LEN(Data1!F2)-FIND("L",Data1!F2)),"Ø","0")," ","")) -> 52 | H5: =VALUE(SUBSTITUTE(SUBSTITUTE(RIGHT(Data1!G2,LEN(Data1!G2)-FIND("L",Data1!G2)),"Ø","0")," ","")) -> 60 | I5: =VALUE(SUBSTITUTE(SUBSTITUTE(RIGHT(Data1!H2,LEN(Data1!H2)-FIND("L",Data1!H2)),"Ø","0")," ","")) -> 68 | J5: =VALUE(SUBSTITUTE(SUBSTITUTE(RIGHT(Data1!I2,LEN(Data1!I2)-FIND("L",Data1!I2)),"Ø","0")," ","")) -> 71 | K5: =VALUE(SUBSTITUTE(SUBSTITUTE(RIGHT(Data1!J2,LEN(Data1!J2)-FIND("L",Data1!J2)),"Ø","0")," ","")) -> 71 | ... O5: =VALUE(SUBSTITUTE(SUBSTITUTE(RIGHT(Data1!N2,LEN(Data1!N2)-FIND("L",Data1!N2)),"Ø","0")," ","")) -> 37
B6: Austin | D6: =VALUE(SUBSTITUTE(SUBSTITUTE(RIGHT(Data1!C3,LEN(Data1!C3)-FIND("L",Data1!C3)),"Ø","0")," ","")) -> 42 | E6: =VALUE(SUBSTITUTE(SUBSTITUTE(RIGHT(Data1!D3,LEN(Data1!D3)-FIND("L",Data1!D3)),"Ø","0")," ","")) -> 45 | F6: =VALUE(SUBSTITUTE(SUBSTITUTE(RIGHT(Data1!E3,LEN(Data1!E3)-FIND("L",Data1!E3)),"Ø","0")," ","")) -> 51 | G6: =VALUE(SUBSTITUTE(SUBSTITUTE(RIGHT(Data1!F3,LEN(Data1!F3)-FIND("L",Data1!F3)),"Ø","0")," ","")) -> 59 | H6: =VALUE(SUBSTITUTE(SUBSTITUTE(RIGHT(Data1!G3,LEN(Data1!G3)-FIND("L",Data1!G3)),"Ø","0")," ","")) -> 67 | I6: =VALUE(SUBSTITUTE(SUBSTITUTE(RIGHT(Data1!H3,LEN(Data1!H3)-FIND("L",Data1!H3)),"Ø","0")," ","")) -> 72 | J6: =VALUE(SUBSTITUTE(SUBSTITUTE(RIGHT(Data1!I3,LEN(Data1!I3)-FIND("L",Data1!I3)),"Ø","0")," ","")) -> 74 | K6: =VALUE(SUBSTITUTE(SUBSTITUTE(RIGHT(Data1!J3,LEN(Data1!J3)-FIND("L",Data1!J3)),"Ø","0")," ","")) -> 75 | ... O6: =VALUE(SUBSTITUTE(SUBSTITUTE(RIGHT(Data1!N3,LEN(Data1!N3)-FIND("L",Data1!N3)),"Ø","0")," ","")) -> 42
B7: Baltimore | D7: =VALUE(SUBSTITUTE(SUBSTITUTE(RIGHT(Data1!C4,LEN(Data1!C4)-FIND("L",Data1!C4)),"Ø","0")," ","")) -> 24 | E7: =VALUE(SUBSTITUTE(SUBSTITUTE(RIGHT(Data1!D4,LEN(Data1!D4)-FIND("L",Data1!D4)),"Ø","0")," ","")) -> 27 | F7: =VALUE(SUBSTITUTE(SUBSTITUTE(RIGHT(Data1!E4,LEN(Data1!E4)-FIND("L",Data1!E4)),"Ø","0")," ","")) -> 34 | G7: =VALUE(SUBSTITUTE(SUBSTITUTE(RIGHT(Data1!F4,LEN(Data1!F4)-FIND("L",Data1!F4)),"Ø","0")," ","")) -> 43 | H7: =VALUE(SUBSTITUTE(SUBSTITUTE(RIGHT(Data1!G4,LEN(Data1!G4)-FIND("L",Data1!G4)),"Ø","0")," ","")) -> 52 | I7: =VALUE(SUBSTITUTE(SUBSTITUTE(RIGHT(Data1!H4,LEN(Data1!H4)-FIND("L",Data1!H4)),"Ø","0")," ","")) -> 62 | J7: =VALUE(SUBSTITUTE(SUBSTITUTE(RIGHT(Data1!I4,LEN(Data1!I4)-FIND("L",Data1!I4)),"Ø","0")," ","")) -> 67 | K7: =VALUE(SUBSTITUTE(SUBSTITUTE(RIGHT(Data1!J4,LEN(Data1!J4)-FIND("L",Data1!J4)),"Ø","0")," ","")) -> 65 | ... O7: =VALUE(SUBSTITUTE(SUBSTITUTE(RIGHT(Data1!N4,LEN(Data1!N4)-FIND("L",Data1!N4)),"Ø","0")," ","")) -> 28
B8: Birmingham | D8: =VALUE(SUBSTITUTE(SUBSTITUTE(RIGHT(Data1!C5,LEN(Data1!C5)-FIND("L",Data1!C5)),"Ø","0")," ","")) -> 34 | E8: =VALUE(SUBSTITUTE(SUBSTITUTE(RIGHT(Data1!D5,LEN(Data1!D5)-FIND("L",Data1!D5)),"Ø","0")," ","")) -> 37 | F8: =VALUE(SUBSTITUTE(SUBSTITUTE(RIGHT(Data1!E5,LEN(Data1!E5)-FIND("L",Data1!E5)),"Ø","0")," ","")) -> 44 | G8: =VALUE(SUBSTITUTE(SUBSTITUTE(RIGHT(Data1!F5,LEN(Data1!F5)-FIND("L",Data1!F5)),"Ø","0")," ","")) -> 51 | H8: =VALUE(SUBSTITUTE(SUBSTITUTE(RIGHT(Data1!G5,LEN(Data1!G5)-FIND("L",Data1!G5)),"Ø","0")," ","")) -> 60 | I8: =VALUE(SUBSTITUTE(SUBSTITUTE(RIGHT(Data1!H5,LEN(Data1!H5)-FIND("L",Data1!H5)),"Ø","0")," ","")) -> 68 | J8: =VALUE(SUBSTITUTE(SUBSTITUTE(RIGHT(Data1!I5,LEN(Data1!I5)-FIND("L",Data1!I5)),"Ø","0")," ","")) -> 71 | K8: =VALUE(SUBSTITUTE(SUBSTITUTE(RIGHT(Data1!J5,LEN(Data1!J5)-FIND("L",Data1!J5)),"Ø","0")," ","")) -> 71 | ... O8: =VALUE(SUBSTITUTE(SUBSTITUTE(RIGHT(Data1!N5,LEN(Data1!N5)-FIND("L",Data1!N5)),"Ø","0")," ","")) -> 36
B9: Boston | D9: =VALUE(SUBSTITUTE(SUBSTITUTE(RIGHT(Data1!C6,LEN(Data1!C6)-FIND("L",Data1!C6)),"Ø","0")," ","")) -> 22 | E9: =VALUE(SUBSTITUTE(SUBSTITUTE(RIGHT(Data1!D6,LEN(Data1!D6)-FIND("L",Data1!D6)),"Ø","0")," ","")) -> 25 | F9: =VALUE(SUBSTITUTE(SUBSTITUTE(RIGHT(Data1!E6,LEN(Data1!E6)-FIND("L",Data1!E6)),"Ø","0")," ","")) -> 31 | G9: =VALUE(SUBSTITUTE(SUBSTITUTE(RIGHT(Data1!F6,LEN(Data1!F6)-FIND("L",Data1!F6)),"Ø","0")," ","")) -> 41 | H9: =VALUE(SUBSTITUTE(SUBSTITUTE(RIGHT(Data1!G6,LEN(Data1!G6)-FIND("L",Data1!G6)),"Ø","0")," ","")) -> 50 | I9: =VALUE(SUBSTITUTE(SUBSTITUTE(RIGHT(Data1!H6,LEN(Data1!H6)-FIND("L",Data1!H6)),"Ø","0")," ","")) -> 60 | J9: =VALUE(SUBSTITUTE(SUBSTITUTE(RIGHT(Data1!I6,LEN(Data1!I6)-FIND("L",Data1!I6)),"Ø","0")," ","")) -> 65 | K9: =VALUE(SUBSTITUTE(SUBSTITUTE(RIGHT(Data1!J6,LEN(Data1!J6)-FIND("L",Data1!J6)),"Ø","0")," ","")) -> 65 | ... O9: =VALUE(SUBSTITUTE(SUBSTITUTE(RIGHT(Data1!N6,LEN(Data1!N6)-FIND("L",Data1!N6)),"Ø","0")," ","")) -> 28
B10: Buffalo | D10: =VALUE(SUBSTITUTE(SUBSTITUTE(RIGHT(Data1!C7,LEN(Data1!C7)-FIND("L",Data1!C7)),"Ø","0")," ","")) -> 19 | E10: =VALUE(SUBSTITUTE(SUBSTITUTE(RIGHT(Data1!D7,LEN(Data1!D7)-FIND("L",Data1!D7)),"Ø","0")," ","")) -> 19 | F10: =VALUE(SUBSTITUTE(SUBSTITUTE(RIGHT(Data1!E7,LEN(Data1!E7)-FIND("L",Data1!E7)),"Ø","0")," ","")) -> 26 | G10: =VALUE(SUBSTITUTE(SUBSTITUTE(RIGHT(Data1!F7,LEN(Data1!F7)-FIND("L",Data1!F7)),"Ø","0")," ","")) -> 37 | H10: =VALUE(SUBSTITUTE(SUBSTITUTE(RIGHT(Data1!G7,LEN(Data1!G7)-FIND("L",Data1!G7)),"Ø","0")," ","")) -> 47 | I10: =VALUE(SUBSTITUTE(SUBSTITUTE(RIGHT(Data1!H7,LEN(Data1!H7)-FIND("L",Data1!H7)),"Ø","0")," ","")) -> 57 | J10: =VALUE(SUBSTITUTE(SUBSTITUTE(RIGHT(Data1!I7,LEN(Data1!I7)-FIND("L",Data1!I7)),"Ø","0")," ","")) -> 62 | K10: =VALUE(SUBSTITUTE(SUBSTITUTE(RIGHT(Data1!J7,LEN(Data1!J7)-FIND("L",Data1!J7)),"Ø","0")," ","")) -> 61 | ... O10: =VALUE(SUBSTITUTE(SUBSTITUTE(RIGHT(Data1!N7,LEN(Data1!N7)-FIND("L",Data1!N7)),"Ø","0")," ","")) -> 24
B11: Charlotte | D11: =VALUE(SUBSTITUTE(SUBSTITUTE(RIGHT(Data1!C8,LEN(Data1!C8)-FIND("L",Data1!C8)),"Ø","0")," ","")) -> 30 | E11: =VALUE(SUBSTITUTE(SUBSTITUTE(RIGHT(Data1!D8,LEN(Data1!D8)-FIND("L",Data1!D8)),"Ø","0")," ","")) -> 33 | F11: =VALUE(SUBSTITUTE(SUBSTITUTE(RIGHT(Data1!E8,LEN(Data1!E8)-FIND("L",Data1!E8)),"Ø","0")," ","")) -> 39 | G11: =VALUE(SUBSTITUTE(SUBSTITUTE(RIGHT(Data1!F8,LEN(Data1!F8)-FIND("L",Data1!F8)),"Ø","0")," ","")) -> 47 | H11: =VALUE(SUBSTITUTE(SUBSTITUTE(RIGHT(Data1!G8,LEN(Data1!G8)-FIND("L",Data1!G8)),"Ø","0")," ","")) -> 56 | I11: =VALUE(SUBSTITUTE(SUBSTITUTE(RIGHT(Data1!H8,LEN(Data1!H8)-FIND("L",Data1!H8)),"Ø","0")," ","")) -> 65 | J11: =VALUE(SUBSTITUTE(SUBSTITUTE(RIGHT(Data1!I8,LEN(Data1!I8)-FIND("L",Data1!I8)),"Ø","0")," ","")) -> 68 | K11: =VALUE(SUBSTITUTE(SUBSTITUTE(RIGHT(Data1!J8,LEN(Data1!J8)-FIND("L",Data1!J8)),"Ø","0")," ","")) -> 67 | ... O11: =VALUE(SUBSTITUTE(SUBSTITUTE(RIGHT(Data1!N8,LEN(Data1!N8)-FIND("L",Data1!N8)),"Ø","0")," ","")) -> 32
B12: Chicago | D12: =VALUE(SUBSTITUTE(SUBSTITUTE(RIGHT(Data1!C9,LEN(Data1!C9)-FIND("L",Data1!C9)),"Ø","0")," ","")) -> 17 | E12: =VALUE(SUBSTITUTE(SUBSTITUTE(RIGHT(Data1!D9,LEN(Data1!D9)-FIND("L",Data1!D9)),"Ø","0")," ","")) -> 20 | F12: =VALUE(SUBSTITUTE(SUBSTITUTE(RIGHT(Data1!E9,LEN(Data1!E9)-FIND("L",Data1!E9)),"Ø","0")," ","")) -> 29 | G12: =VALUE(SUBSTITUTE(SUBSTITUTE(RIGHT(Data1!F9,LEN(Data1!F9)-FIND("L",Data1!F9)),"Ø","0")," ","")) -> 39 | H12: =VALUE(SUBSTITUTE(SUBSTITUTE(RIGHT(Data1!G9,LEN(Data1!G9)-FIND("L",Data1!G9)),"Ø","0")," ","")) -> 48 | I12: =VALUE(SUBSTITUTE(SUBSTITUTE(RIGHT(Data1!H9,LEN(Data1!H9)-FIND("L",Data1!H9)),"Ø","0")," ","")) -> 58 | J12: =VALUE(SUBSTITUTE(SUBSTITUTE(RIGHT(Data1!I9,LEN(Data1!I9)-FIND("L",Data1!I9)),"Ø","0")," ","")) -> 64 | K12: =VALUE(SUBSTITUTE(SUBSTITUTE(RIGHT(Data1!J9,LEN(Data1!J9)-FIND("L",Data1!J9)),"Ø","0")," ","")) -> 63 | ... O12: =VALUE(SUBSTITUTE(SUBSTITUTE(RIGHT(Data1!N9,LEN(Data1!N9)-FIND("L",Data1!N9)),"Ø","0")," ","")) -> 21
B13: Cincinnati | D13: =VALUE(SUBSTITUTE(SUBSTITUTE(RIGHT(Data1!C10,LEN(Data1!C10)-FIND("L",Data1!C10)),"Ø","0")," ","")) -> 22 | E13: =VALUE(SUBSTITUTE(SUBSTITUTE(RIGHT(Data1!D10,LEN(Data1!D10)-FIND("L",Data1!D10)),"Ø","0")," ","")) -> 25 | F13: =VALUE(SUBSTITUTE(SUBSTITUTE(RIGHT(Data1!E10,LEN(Data1!E10)-FIND("L",Data1!E10)),"Ø","0")," ","")) -> 33 | G13: =VALUE(SUBSTITUTE(SUBSTITUTE(RIGHT(Data1!F10,LEN(Data1!F10)-FIND("L",Data1!F10)),"Ø","0")," ","")) -> 42 | H13: =VALUE(SUBSTITUTE(SUBSTITUTE(RIGHT(Data1!G10,LEN(Data1!G10)-FIND("L",Data1!G10)),"Ø","0")," ","")) -> 52 | I13: =VALUE(SUBSTITUTE(SUBSTITUTE(RIGHT(Data1!H10,LEN(Data1!H10)-FIND("L",Data1!H10)),"Ø","0")," ","")) -> 61 | J13: =VALUE(SUBSTITUTE(SUBSTITUTE(RIGHT(Data1!I10,LEN(Data1!I10)-FIND("L",Data1!I10)),"Ø","0")," ","")) -> 65 | K13: =VALUE(SUBSTITUTE(SUBSTITUTE(RIGHT(Data1!J10,LEN(Data1!J10)-FIND("L",Data1!J10)),"Ø","0")," ","")) -> 63 | ... O13: =VALUE(SUBSTITUTE(SUBSTITUTE(RIGHT(Data1!N10,LEN(Data1!N10)-FIND("L",Data1!N10)),"Ø","0")," ","")) -> 26
B14: Cleveland | D14: =VALUE(SUBSTITUTE(SUBSTITUTE(RIGHT(Data1!C11,LEN(Data1!C11)-FIND("L",Data1!C11)),"Ø","0")," ","")) -> 22 | E14: =VALUE(SUBSTITUTE(SUBSTITUTE(RIGHT(Data1!D11,LEN(Data1!D11)-FIND("L",Data1!D11)),"Ø","0")," ","")) -> 24 | F14: =VALUE(SUBSTITUTE(SUBSTITUTE(RIGHT(Data1!E11,LEN(Data1!E11)-FIND("L",Data1!E11)),"Ø","0")," ","")) -> 30 | G14: =VALUE(SUBSTITUTE(SUBSTITUTE(RIGHT(Data1!F11,LEN(Data1!F11)-FIND("L",Data1!F11)),"Ø","0")," ","")) -> 40 | H14: =VALUE(SUBSTITUTE(SUBSTITUTE(RIGHT(Data1!G11,LEN(Data1!G11)-FIND("L",Data1!G11)),"Ø","0")," ","")) -> 50 | I14: =VALUE(SUBSTITUTE(SUBSTITUTE(RIGHT(Data1!H11,LEN(Data1!H11)-FIND("L",Data1!H11)),"Ø","0")," ","")) -> 60 | J14: =VALUE(SUBSTITUTE(SUBSTITUTE(RIGHT(Data1!I11,LEN(Data1!I11)-FIND("L",Data1!I11)),"Ø","0")," ","")) -> 64 | K14: =VALUE(SUBSTITUTE(SUBSTITUTE(RIGHT(Data1!J11,LEN(Data1!J11)-FIND("L",Data1!J11)),"Ø","0")," ","")) -> 63 | ... O14: =VALUE(SUBSTITUTE(SUBSTITUTE(RIGHT(Data1!N11,LEN(Data1!N11)-FIND("L",Data1!N11)),"Ø","0")," ","")) -> 26
B15: Columbus | D15: =VALUE(SUBSTITUTE(SUBSTITUTE(RIGHT(Data1!C12,LEN(Data1!C12)-FIND("L",Data1!C12)),"Ø","0")," ","")) -> 23 | E15: =VALUE(SUBSTITUTE(SUBSTITUTE(RIGHT(Data1!D12,LEN(Data1!D12)-FIND("L",Data1!D12)),"Ø","0")," ","")) -> 25 | F15: =VALUE(SUBSTITUTE(SUBSTITUTE(RIGHT(Data1!E12,LEN(Data1!E12)-FIND("L",Data1!E12)),"Ø","0")," ","")) -> 33 | G15: =VALUE(SUBSTITUTE(SUBSTITUTE(RIGHT(Data1!F12,LEN(Data1!F12)-FIND("L",Data1!F12)),"Ø","0")," ","")) -> 43 | H15: =VALUE(SUBSTITUTE(SUBSTITUTE(RIGHT(Data1!G12,LEN(Data1!G12)-FIND("L",Data1!G12)),"Ø","0")," ","")) -> 52 | I15: =VALUE(SUBSTITUTE(SUBSTITUTE(RIGHT(Data1!H12,LEN(Data1!H12)-FIND("L",Data1!H12)),"Ø","0")," ","")) -> 62 | J15: =VALUE(SUBSTITUTE(SUBSTITUTE(RIGHT(Data1!I12,LEN(Data1!I12)-FIND("L",Data1!I12)),"Ø","0")," ","")) -> 66 | K15: =VALUE(SUBSTITUTE(SUBSTITUTE(RIGHT(Data1!J12,LEN(Data1!J12)-FIND("L",Data1!J12)),"Ø","0")," ","")) -> 64 | ... O15: =VALUE(SUBSTITUTE(SUBSTITUTE(RIGHT(Data1!N12,LEN(Data1!N12)-FIND("L",Data1!N12)),"Ø","0")," ","")) -> 27
B16: Dallas | D16: =VALUE(SUBSTITUTE(SUBSTITUTE(RIGHT(Data1!C13,LEN(Data1!C13)-FIND("L",Data1!C13)),"Ø","0")," ","")) -> 37 | E16: =VALUE(SUBSTITUTE(SUBSTITUTE(RIGHT(Data1!D13,LEN(Data1!D13)-FIND("L",Data1!D13)),"Ø","0")," ","")) -> 41 | F16: =VALUE(SUBSTITUTE(SUBSTITUTE(RIGHT(Data1!E13,LEN(Data1!E13)-FIND("L",Data1!E13)),"Ø","0")," ","")) -> 49 | G16: =VALUE(SUBSTITUTE(SUBSTITUTE(RIGHT(Data1!F13,LEN(Data1!F13)-FIND("L",Data1!F13)),"Ø","0")," ","")) -> 56 | H16: =VALUE(SUBSTITUTE(SUBSTITUTE(RIGHT(Data1!G13,LEN(Data1!G13)-FIND("L",Data1!G13)),"Ø","0")," ","")) -> 65 | I16: =VALUE(SUBSTITUTE(SUBSTITUTE(RIGHT(Data1!H13,LEN(Data1!H13)-FIND("L",Data1!H13)),"Ø","0")," ","")) -> 73 | J16: =VALUE(SUBSTITUTE(SUBSTITUTE(RIGHT(Data1!I13,LEN(Data1!I13)-FIND("L",Data1!I13)),"Ø","0")," ","")) -> 77 | K16: =VALUE(SUBSTITUTE(SUBSTITUTE(RIGHT(Data1!J13,LEN(Data1!J13)-FIND("L",Data1!J13)),"Ø","0")," ","")) -> 77 | ... O16: =VALUE(SUBSTITUTE(SUBSTITUTE(RIGHT(Data1!N13,LEN(Data1!N13)-FIND("L",Data1!N13)),"Ø","0")," ","")) -> 39
B17: Denver | D17: =VALUE(SUBSTITUTE(SUBSTITUTE(RIGHT(Data1!C14,LEN(Data1!C14)-FIND("L",Data1!C14)),"Ø","0")," ","")) -> 17 | E17: =VALUE(SUBSTITUTE(SUBSTITUTE(RIGHT(Data1!D14,LEN(Data1!D14)-FIND("L",Data1!D14)),"Ø","0")," ","")) -> 20 | F17: =VALUE(SUBSTITUTE(SUBSTITUTE(RIGHT(Data1!E14,LEN(Data1!E14)-FIND("L",Data1!E14)),"Ø","0")," ","")) -> 26 | G17: =VALUE(SUBSTITUTE(SUBSTITUTE(RIGHT(Data1!F14,LEN(Data1!F14)-FIND("L",Data1!F14)),"Ø","0")," ","")) -> 34 | H17: =VALUE(SUBSTITUTE(SUBSTITUTE(RIGHT(Data1!G14,LEN(Data1!G14)-FIND("L",Data1!G14)),"Ø","0")," ","")) -> 44 | I17: =VALUE(SUBSTITUTE(SUBSTITUTE(RIGHT(Data1!H14,LEN(Data1!H14)-FIND("L",Data1!H14)),"Ø","0")," ","")) -> 53 | J17: =VALUE(SUBSTITUTE(SUBSTITUTE(RIGHT(Data1!I14,LEN(Data1!I14)-FIND("L",Data1!I14)),"Ø","0")," ","")) -> 59 | K17: =VALUE(SUBSTITUTE(SUBSTITUTE(RIGHT(Data1!J14,LEN(Data1!J14)-FIND("L",Data1!J14)),"Ø","0")," ","")) -> 57 | ... O17: =VALUE(SUBSTITUTE(SUBSTITUTE(RIGHT(Data1!N14,LEN(Data1!N14)-FIND("L",Data1!N14)),"Ø","0")," ","")) -> 17
... B54: Virginia Beach | D54: =VALUE(SUBSTITUTE(SUBSTITUTE(RIGHT(Data1!C51,LEN(Data1!C51)-FIND("L",Data1!C51)),"Ø","0")," ","")) -> 33 | E54: =VALUE(SUBSTITUTE(SUBSTITUTE(RIGHT(Data1!D51,LEN(Data1!D51)-FIND("L",Data1!D51)),"Ø","0")," ","")) -> 34 | F54: =VALUE(SUBSTITUTE(SUBSTITUTE(RIGHT(Data1!E51,LEN(Data1!E51)-FIND("L",Data1!E51)),"Ø","0")," ","")) -> 41 | G54: =VALUE(SUBSTITUTE(SUBSTITUTE(RIGHT(Data1!F51,LEN(Data1!F51)-FIND("L",Data1!F51)),"Ø","0")," ","")) -> 49 | H54: =VALUE(SUBSTITUTE(SUBSTITUTE(RIGHT(Data1!G51,LEN(Data1!G51)-FIND("L",Data1!G51)),"Ø","0")," ","")) -> 58 | I54: =VALUE(SUBSTITUTE(SUBSTITUTE(RIGHT(Data1!H51,LEN(Data1!H51)-FIND("L",Data1!H51)),"Ø","0")," ","")) -> 67 | J54: =VALUE(SUBSTITUTE(SUBSTITUTE(RIGHT(Data1!I51,LEN(Data1!I51)-FIND("L",Data1!I51)),"Ø","0")," ","")) -> 72 | K54: =VALUE(SUBSTITUTE(SUBSTITUTE(RIGHT(Data1!J51,LEN(Data1!J51)-FIND("L",Data1!J51)),"Ø","0")," ","")) -> 71 | ... O54: =VALUE(SUBSTITUTE(SUBSTITUTE(RIGHT(Data1!N51,LEN(Data1!N51)-FIND("L",Data1!N51)),"Ø","0")," ","")) -> 36
B55: Lowest Tempeatures | D55: =MIN(D30:D54) -> 8 | E55: =MIN(E30:E54) -> 13 | F55: =MIN(F30:F54) -> 24 | G55: =MIN(G30:G54) -> 37 | H55: =MIN(H30:H54) -> 46 | I55: =MIN(I30:I54) -> 52 | J55: =MIN(J30:J54) -> 54 | K55: =MIN(K30:K54) -> 55 | ... O55: =MIN(O30:O54) -> 12
B57: Check Sum | D57: {=CheckSumLow} -> 172862 | E57: 185534 | F57: 214009 | G57: 248444 | H57: 287509 | I57: 323773 | J57: 343816 | K57: 340769 | L57: 312610 | M57: 266825 | N57: 222505 | O57: 182849
D62: =MIN(CS_TableLow) -> 8

Sheet MonthSorted
J1: Workings
B2: Sorted Table of High Temperatures | J2: month | K2: =MONTH(DATEVALUE(C3&" 1")) -> 1
B3: For the Month of: | C3: Jan | J3: city | K3: high temp | L3: adjustment | M3: rank | N3: sort order
A4: Position | B4: City | C4: High Temperature
A5: {=CS_Int} -> 1 | B5: {=INDEX($J$5:$J$54,$N5)} -> Miami | C5: {=INDEX($K$5:$K$54,$N5)} -> 76 | J5: =SummaryHigh!B5 -> Atlanta | K5: {=INDEX(SummaryHigh!$D$5:$O$54, MATCH(J5, SummaryHigh!$B$5:$B$54, 0), $K$2)} -> 52 | L5: =K5-ROW()/1000 -> 51.995 | M5: =RANK(L5,$L$5:$L$54,0) -> 19 | N5: =MATCH(A5,$M$5:$M$54,0) -> 24 | O5: =SUM(K5:L5) -> 103.995
A6: 2 | B6: {=INDEX($J$5:$J$54,$N6)} -> Orlando | C6: {=INDEX($K$5:$K$54,$N6)} -> 71 | J6: =SummaryHigh!B6 -> Austin | K6: {=INDEX(SummaryHigh!$D$5:$O$54, MATCH(J6, SummaryHigh!$B$5:$B$54, 0), $K$2)} -> 62 | L6: =K6-ROW()/1000 -> 61.994 | M6: =RANK(L6,$L$5:$L$54,0) -> 11 | N6: =MATCH(A6,$M$5:$M$54,0) -> 31
A7: 3 | B7: {=INDEX($J$5:$J$54,$N7)} -> Tampa | C7: {=INDEX($K$5:$K$54,$N7)} -> 70 | J7: =SummaryHigh!B7 -> Baltimore | K7: {=INDEX(SummaryHigh!$D$5:$O$54, MATCH(J7, SummaryHigh!$B$5:$B$54, 0), $K$2)} -> 41 | L7: =K7-ROW()/1000 -> 40.993 | M7: =RANK(L7,$L$5:$L$54,0) -> 31 | N7: =MATCH(A7,$M$5:$M$54,0) -> 49
A8: 4 | B8: {=INDEX($J$5:$J$54,$N8)} -> Phoenix | C8: {=INDEX($K$5:$K$54,$N8)} -> 69 | J8: =SummaryHigh!B8 -> Birmingham | K8: {=INDEX(SummaryHigh!$D$5:$O$54, MATCH(J8, SummaryHigh!$B$5:$B$54, 0), $K$2)} -> 54 | L8: =K8-ROW()/1000 -> 53.992 | M8: =RANK(L8,$L$5:$L$54,0) -> 17 | N8: =MATCH(A8,$M$5:$M$54,0) -> 33
A9: 5 | B9: {=INDEX($J$5:$J$54,$N9)} -> Riverside | C9: {=INDEX($K$5:$K$54,$N9)} -> 69 | J9: =SummaryHigh!B9 -> Boston | K9: {=INDEX(SummaryHigh!$D$5:$O$54, MATCH(J9, SummaryHigh!$B$5:$B$54, 0), $K$2)} -> 36 | L9: =K9-ROW()/1000 -> 35.991 | M9: =RANK(L9,$L$5:$L$54,0) -> 40 | N9: =MATCH(A9,$M$5:$M$54,0) -> 39
A10: 6 | B10: {=INDEX($J$5:$J$54,$N10)} -> Los Angeles | C10: {=INDEX($K$5:$K$54,$N10)} -> 68 | J10: =SummaryHigh!B10 -> Buffalo | K10: {=INDEX(SummaryHigh!$D$5:$O$54, MATCH(J10, SummaryHigh!$B$5:$B$54, 0), $K$2)} -> 31 | L10: =K10-ROW()/1000 -> 30.99 | M10: =RANK(L10,$L$5:$L$54,0) -> 47 | N10: =MATCH(A10,$M$5:$M$54,0) -> 21
A11: 7 | B11: {=INDEX($J$5:$J$54,$N11)} -> Jacksonville | C11: {=INDEX($K$5:$K$54,$N11)} -> 65 | J11: =SummaryHigh!B11 -> Charlotte | K11: {=INDEX(SummaryHigh!$D$5:$O$54, MATCH(J11, SummaryHigh!$B$5:$B$54, 0), $K$2)} -> 51 | L11: =K11-ROW()/1000 -> 50.989 | M11: =RANK(L11,$L$5:$L$54,0) -> 20 | N11: =MATCH(A11,$M$5:$M$54,0) -> 18
A12: 8 | B12: {=INDEX($J$5:$J$54,$N12)} -> San Diego | C12: {=INDEX($K$5:$K$54,$N12)} -> 65 | J12: =SummaryHigh!B12 -> Chicago | K12: {=INDEX(SummaryHigh!$D$5:$O$54, MATCH(J12, SummaryHigh!$B$5:$B$54, 0), $K$2)} -> 31 | L12: =K12-ROW()/1000 -> 30.988 | M12: =RANK(L12,$L$5:$L$54,0) -> 48 | N12: =MATCH(A12,$M$5:$M$54,0) -> 44
A13: 9 | B13: {=INDEX($J$5:$J$54,$N13)} -> Houston | C13: {=INDEX($K$5:$K$54,$N13)} -> 63 | J13: =SummaryHigh!B13 -> Cincinnati | K13: {=INDEX(SummaryHigh!$D$5:$O$54, MATCH(J13, SummaryHigh!$B$5:$B$54, 0), $K$2)} -> 40 | L13: =K13-ROW()/1000 -> 39.987 | M13: =RANK(L13,$L$5:$L$54,0) -> 32 | N13: =MATCH(A13,$M$5:$M$54,0) -> 16
A14: 10 | B14: {=INDEX($J$5:$J$54,$N14)} -> San Antonio | C14: {=INDEX($K$5:$K$54,$N14)} -> 63 | J14: =SummaryHigh!B14 -> Cleveland | K14: {=INDEX(SummaryHigh!$D$5:$O$54, MATCH(J14, SummaryHigh!$B$5:$B$54, 0), $K$2)} -> 34 | L14: =K14-ROW()/1000 -> 33.986 | M14: =RANK(L14,$L$5:$L$54,0) -> 44 | N14: =MATCH(A14,$M$5:$M$54,0) -> 43
A15: 11 | B15: {=INDEX($J$5:$J$54,$N15)} -> Austin | C15: {=INDEX($K$5:$K$54,$N15)} -> 62 | J15: =SummaryHigh!B15 -> Columbus | K15: {=INDEX(SummaryHigh!$D$5:$O$54, MATCH(J15, SummaryHigh!$B$5:$B$54, 0), $K$2)} -> 37 | L15: =K15-ROW()/1000 -> 36.985 | M15: =RANK(L15,$L$5:$L$54,0) -> 37 | N15: =MATCH(A15,$M$5:$M$54,0) -> 2
A16: 12 | B16: {=INDEX($J$5:$J$54,$N16)} -> New Orleans | C16: {=INDEX($K$5:$K$54,$N16)} -> 62 | J16: =SummaryHigh!B16 -> Dallas | K16: {=INDEX(SummaryHigh!$D$5:$O$54, MATCH(J16, SummaryHigh!$B$5:$B$54, 0), $K$2)} -> 57 | L16: =K16-ROW()/1000 -> 56.984 | M16: =RANK(L16,$L$5:$L$54,0) -> 15 | N16: =MATCH(A16,$M$5:$M$54,0) -> 28
A17: 13 | B17: {=INDEX($J$5:$J$54,$N17)} -> Las Vegas | C17: {=INDEX($K$5:$K$54,$N17)} -> 58 | J17: =SummaryHigh!B17 -> Denver | K17: {=INDEX(SummaryHigh!$D$5:$O$54, MATCH(J17, SummaryHigh!$B$5:$B$54, 0), $K$2)} -> 45 | L17: =K17-ROW()/1000 -> 44.983 | M17: =RANK(L17,$L$5:$L$54,0) -> 29 | N17: =MATCH(A17,$M$5:$M$54,0) -> 20
... A54: 50 | B54: {=INDEX($J$5:$J$54,$N54)} -> Minneapolis | C54: {=INDEX($K$5:$K$54,$N54)} -> 24 | J54: =SummaryHigh!B54 -> Virginia Beach | K54: {=INDEX(SummaryHigh!$D$5:$O$54, MATCH(J54, SummaryHigh!$B$5:$B$54, 0), $K$2)} -> 48 | L54: =K54-ROW()/1000 -> 47.946 | M54: =RANK(L54,$L$5:$L$54,0) -> 25 | N54: =MATCH(A54,$M$5:$M$54,0) -> 26
A56: Check Sum | B56: =CheckSumSortCity -> 382116 | C56: =CheckSumSortTemp -> 203895

Sheet Part 2
A1: This sheet is intentionally blank

Sheet Scenarios
B2: Part 2 - Introduction
B4: Your task is to calculate the future account balance of a savings account opened today with certain provided terms.
B5: Terms will be provided for Interest Rate, Number of Years and Additional Payments. There will also be an Initial Depsoit Amount.
B6: You will need to use these terms to look up the Initial Deposit Amount, and then calculate the future account balance.
B8: Interest Rate
B9: The account earns interest at one of the 6 following annual rates:
B10: 0.05
B11: 0.055
B12: 0.06
B13: 0.065
B14: 0.07
B15: 0.075
B16: Interest is paid into the account at the end of every 12 month period.
B18: Number of Years
B19: The account will be active for one of the following number of years, starting today:
B20: 4
B21: 5
B22: 6
B23: 7
B24: 8
B26: Additional Payments
B27: At the end of every 12 month period (beginning one year after today), an additional payment is deposited into the account.
B28: The additional payment will be one of the 4 following amounts:
B29: 1500
B30: 1800
B31: 2200
B32: 2700
B34: Initial Deposit
B35: When the account is opened today, an initial deposit is made into the account.
B36: The size of the deposit must be looked up from a table depending upon the chosen values for Interest Rate, Number of Years and Additional Payments.
B37: There is a table provided for each interest rate value (see worksheet "Rate_550" for the 5.50% rate for example).
B38: Each table has 20 initial deposit amounts, one for each combination of Years and Additional Payments.
B40: The amounts are located in cells C3:G6 of each table, with the rate in cell A1, the number of years in cells B2:G2 and the Additional Payment at cells B3:B6.
B42: Assumptions and Calculations
B44: Your task is to populate the green cells in the 'Initial Deposit' column and 'Final Account Balance' column for each of the 30 Account Numbers.
B45: Do your workings in the grey 'helper cells' box in columns I to X, so that the green cells contain only your final answers. Then answer the assignment questions.
B47: HINTS:
B48: 1) Try and write flexible formulas that can be copied down the entire column of 30 accounts. This will be the quickest way.
B49: 2) You may wish to use the INDIRECT function to find the Initial Deposit. Note that the Interest Rate * 10000 will give the number (500 to 750) that appears in the worksheet tab name.
B50: 3) You may wish to use the FV function to find the Final Account Balance. Make sure the Final Account Balance is a positive number.
...

Sheet Rate_500
A1: 0.05 | B1: <-- Rate | C1: Number of Years (Across Top Row)
B2: Purchase Price (PV) in middle | C2: 4 | D2: 5 | E2: 6 | F2: 7 | G2: 8
A3: Pmt per Year | B3: 1500 | C3: 5530 | D3: 7840 | E3: 7440 | F3: 5940 | G3: 7510
A4: (Down | B4: 1800 | C4: 5850 | D4: 6160 | E4: 7990 | F4: 7300 | G4: 7110
A5: Left | B5: 2200 | C5: 5270 | D5: 7900 | E5: 6250 | F5: 5750 | G5: 6070
A6: Column) | B6: 2700 | C6: 6950 | D6: 5860 | E6: 7420 | F6: 7930 | G6: 6170

Sheet Rate_550
A1: 0.055 | B1: <-- Rate | C1: Number of Years (Across Top Row)
B2: Purchase Price (PV) in middle | C2: 4 | D2: 5 | E2: 6 | F2: 7 | G2: 8
A3: Pmt per Year | B3: 1500 | C3: 7620 | D3: 7540 | E3: 6660 | F3: 6120 | G3: 7520
A4: (Down | B4: 1800 | C4: 5940 | D4: 6720 | E4: 7720 | F4: 6860 | G4: 7210
A5: Left | B5: 2200 | C5: 6060 | D5: 7930 | E5: 7600 | F5: 5940 | G5: 5980
A6: Column) | B6: 2700 | C6: 6430 | D6: 5960 | E6: 6400 | F6: 5560 | G6: 5810

Sheet Rate_600
A1: 0.06 | B1: <-- Rate | C1: Number of Years (Across Top Row)
B2: Purchase Price (PV) in middle | C2: 4 | D2: 5 | E2: 6 | F2: 7 | G2: 8
A3: Pmt per Year | B3: 1500 | C3: 5260 | D3: 6350 | E3: 6810 | F3: 5650 | G3: 6970
A4: (Down | B4: 1800 | C4: 7860 | D4: 6200 | E4: 5820 | F4: 5870 | G4: 5200
A5: Left | B5: 2200 | C5: 7730 | D5: 6240 | E5: 6980 | F5: 5920 | G5: 5190
A6: Column) | B6: 2700 | C6: 5120 | D6: 5040 | E6: 7440 | F6: 5640 | G6: 5740

Sheet Rate_650
A1: 0.065 | B1: <-- Rate | C1: Number of Years (Across Top Row)
B2: Purchase Price (PV) in middle | C2: 4 | D2: 5 | E2: 6 | F2: 7 | G2: 8
A3: Pmt per Year | B3: 1500 | C3: 5100 | D3: 6270 | E3: 6700 | F3: 6410 | G3: 7600
A4: (Down | B4: 1800 | C4: 6280 | D4: 6110 | E4: 7600 | F4: 6740 | G4: 6090
A5: Left | B5: 2200 | C5: 7240 | D5: 7490 | E5: 5130 | F5: 6240 | G5: 5910
A6: Column) | B6: 2700 | C6: 7940 | D6: 5960 | E6: 5450 | F6: 7070 | G6: 6870

Sheet Rate_700
A1: 0.07 | B1: <-- Rate | C1: Number of Years (Across Top Row)
B2: Purchase Price (PV) in middle | C2: 4 | D2: 5 | E2: 6 | F2: 7 | G2: 8
A3: Pmt per Year | B3: 1500 | C3: 6150 | D3: 7690 | E3: 6230 | F3: 6440 | G3: 7160
A4: (Down | B4: 1800 | C4: 7350 | D4: 5030 | E4: 7780 | F4: 6250 | G4: 6690
A5: Left | B5: 2200 | C5: 5610 | D5: 7680 | E5: 5130 | F5: 7260 | G5: 7350
A6: Column) | B6: 2700 | C6: 6550 | D6: 5380 | E6: 6330 | F6: 7020 | G6: 6920

Sheet Rate_750
A1: 0.075 | B1: <-- Rate | C1: Number of Years (Across Top Row)
B2: Purchase Price (PV) in middle | C2: 4 | D2: 5 | E2: 6 | F2: 7 | G2: 8
A3: Pmt per Year | B3: 1500 | C3: 6240 | D3: 5320 | E3: 7500 | F3: 5770 | G3: 5220
A4: (Down | B4: 1800 | C4: 5950 | D4: 7680 | E4: 5450 | F4: 5500 | G4: 6120
A5: Left | B5: 2200 | C5: 7420 | D5: 6480 | E5: 5480 | F5: 6430 | G5: 5480
A6: Column) | B6: 2700 | C6: 7020 | D6: 7590 | E6: 5280 | F6: 5240 | G6: 6560
